Workbook
Name BP: BP!$B$4:$J$77

Sheet BP
A3: ($ em milhões)
A4: Código da Conta | B4: Descrição da Conta | C4: 2024 | D4: 2023 | E4: 2022 | F4: 2021 | G4: 2020 | H4: 2019 | I4: 2018 | J4: 2017
A5: 1 | B5: Ativo Total | C5: 4466987 | D5: 4581833 | E5: 4199825 | F5: 3754136 | G5: 2824635 | H5: 1945403 | I5: 1789529 | J5: 1733859
A6: 1.01 | B6: Ativo Circulante | C6: 2967747 | D6: 3575173 | E6: 3430062 | F6: 3120040 | G6: 2211237 | H6: 1471763 | I6: 1418740 | J6: 1411332
A7: 1.01.01 | B7: Caixa e Equivalentes de Caixa | C7: 566929 | D7: 591375 | E7: 426576 | F7: 359007 | G7: 544162 | H7: 460714 | I7: 393348 | J7: 387826
A8: 1.01.02 | B8: Aplicações Financeiras | C8: 0 | D8: 0 | E8: 0 | F8: 0 | G8: 0 | H8: 0 | I8: 0 | J8: 0
A9: 1.01.03 | B9: Contas a Receber | C9: 860937 | D9: 1326360 | E9: 1132483 | F9: 762625 | G9: 698044 | H9: 258642 | I9: 235282 | J9: 276246
A10: 1.01.04 | B10: Estoques | C10: 1096246 | D10: 1256483 | E10: 1390723 | F10: 1690347 | G10: 645750 | H10: 494422 | I10: 534726 | J10: 506539
A11: 1.01.06 | B11: Tributos a Recuperar | C11: 301400 | D11: 304370 | E11: 361523 | F11: 176025 | G11: 221036 | H11: 124615 | I11: 129445 | J11: 142158
A12: 1.01.06.01 | B12: Tributos Correntes a Recuperar | C12: 301400 | D12: 304370 | E12: 361523 | F12: 176025 | G12: 221036 | H12: 124615 | I12: 129445 | J12: 0
A13: 1.01.06.01.01 | B13: Tributos a Recuperar | C13: 200109 | D13: 210811 | E13: 309169 | F13: 157222 | G13: 183356 | H13: 87826 | I13: 101769 | J13: 0
A14: 1.01.06.01.02 | B14: Imposto de Renda e Contribuição Social a Recuperar | C14: 101291 | D14: 0 | E14: 0 | F14: 0 | G14: 0 | H14: 0 | I14: 0 | J14: 0
A15: 1.01.08 | B15: Outros Ativos Cirulantes | C15: 142235 | D15: 96585 | E15: 118748 | F15: 132036 | G15: 102245 | H15: 133370 | I15: 125939 | J15: 98563
A16: 1.01.08.03 | B16: Outros | C16: 142235 | D16: 96585 | E16: 118748 | F16: 132036 | G16: 102245 | H16: 133370 | I16: 125939 | J16: 98563
A17: 1.01.08.03.01 | B17: Partes Relacionadas | C17: 21658 | D17: 12382 | E17: 13997 | F17: 14502 | G17: 20410 | H17: 20378 | I17: 21103 | J17: 12383
... A27: 1.02.01.10.05 | B27: Depósitos Judiciais | C27: 35760 | D27: 0 | E27: 0 | F27: 0 | G27: 0 | H27: 0 | I27: 0 | J27: 0
B28: ATIVO FIXO | C28: =SUM(C29,C32,C35) -> 733438 | D28: =SUM(D29,D32,D35) -> 504314 | E28: =SUM(E29,E32,E35) -> 385891 | F28: =SUM(F29,F32,F35) -> 294114 | G28: =SUM(G29,G32,G35) -> 275813 | H28: =SUM(H29,H32,H35) -> 267289 | I28: =SUM(I29,I32,I35) -> 178249 | J28: =SUM(J29,J32,J35) -> 172866
A29: 1.02.02 | B29: Investimentos | C29: 256770 | D29: 226969 | E29: 164127 | F29: 114226 | G29: 91692 | H29: 73433 | I29: 48087 | J29: 53604
A30: 1.02.02.01 | B30: Participações Societárias | C30: 256770 | D30: 226969 | E30: 164127 | F30: 114226 | G30: 91692 | H30: 73433 | I30: 48087 | J30: 53604
A31: 1.02.02.01.01 | B31: Participações em Coligadas | C31: 136724 | D31: 226969 | E31: 131714 | F31: 76284 | G31: 53154 | H31: 27317 | I31: 8303 | J31: 0
A32: 1.02.03 | B32: Imobilizado | C32: 155481 | D32: 146818 | E32: 110987 | F32: 92894 | G32: 86298 | H32: 88718 | I32: 50746 | J32: 57092
A33: 1.02.03.01 | B33: Imobilizado em Operação | C33: 125036 | D33: 116974 | E33: 84915 | F33: 60279 | G33: 47700 | H33: 0 | I33: 0 | J33: 0
A34: 1.02.03.02 | B34: Direito de Uso em Arrendamento | C34: 30445 | D34: 29844 | E34: 26072 | F34: 32615 | G34: 38598 | H34: 41694 | I34: 0 | J34: 0
A35: 1.02.04 | B35: Intangível | C35: 321187 | D35: 130527 | E35: 110777 | F35: 86994 | G35: 97823 | H35: 105138 | I35: 79416 | J35: 62170
A36: 2 | B36: Passivo Total | C36: 4466987 | D36: 4581833 | E36: 4199825 | F36: 3754136 | G36: 2824635 | H36: 1945403 | I36: 1789529 | J36: 1733859
A37: 2.01 | B37: Passivo Circulante | C37: 1503102 | D37: 1934265 | E37: 1773213 | F37: 1937651 | G37: 1370932 | H37: 1178943 | I37: 1111886 | J37: 1090782
A38: 2.01.01 | B38: Obrigações Sociais e Trabalhistas | C38: 105953 | D38: 80891 | E38: 42753 | F38: 38387 | G38: 33263 | H38: 20281 | I38: 18205 | J38: 20122
A39: 2.01.02 | B39: Fornecedores | C39: 658247 | D39: 832121 | E39: 594245 | F39: 1186214 | G39: 562210 | H39: 383964 | I39: 449260 | J39: 486141
A40: 2.01.02.01 | B40: Fornecedores Nacionais | C40: 105953 | D40: 191211 | E40: 290682 | F40: 280741 | G40: 207963 | H40: 196025 | I40: 280194 | J40: 0
A41: 2.01.02.01.01 | B41: Fornecedores | C41: 167077 | D41: 0 | E41: 0 | F41: 0 | G41: 0 | H41: 0 | I41: 0 | J41: 0
A42: 2.01.02.01.02 | B42: Fornecedores - Convênio | C42: 491170 | D42: 0 | E42: 0 | F42: 0 | G42: 0 | H42: 0 | I42: 0 | J42: 0
A43: 2.01.03 | B43: Obrigações Fiscais | C43: 102656 | D43: 73369 | E43: 192806 | F43: 52814 | G43: 32037 | H43: 24035 | I43: 21563 | J43: 35970
A44: 2.01.03.01 | B44: Obrigações Fiscais Federais | C44: 100299 | D44: 60165 | E44: 180197 | F44: 40831 | G44: 27643 | H44: 19004 | I44: 20242 | J44: 0
A45: 2.01.03.01.02 | B45: Tributos a Recolher | C45: 93811 | D45: 0 | E45: 0 | F45: 0 | G45: 0 | H45: 0 | I45: 0 | J45: 0
A46: 2.01.04 | B46: Empréstimos e Financiamentos | C46: 341080 | D46: 694839 | E46: 655704 | F46: 400196 | G46: 461373 | H46: 601728 | I46: 519434 | J46: 439705
A47: 2.01.05 | B47: Outras Obrigações | C47: 156265 | D47: 123124 | E47: 118263 | F47: 95975 | G47: 135275 | H47: 57980 | I47: 24220 | J47: 19028
A48: 2.01.05.01 | B48: Passivos com Partes Relacionadas | C48: 1205 | D48: 2949 | E48: 1140 | F48: 745 | G48: 1213 | H48: 763 | I48: 755 | J48: 3814
... A76: 2.03.08 | B76: Outros Resultados Abrangentes | C76: 0 | D76: 0 | E76: 0 | F76: 0 | G76: 0 | H76: 0 | I76: 0 | J76: 0
A77: TOTAL DO PASSIVO E PATRIMÔNIO LÍQUIDO | C77: =SUM(C68,C36) -> 6113108 | D77: =SUM(D68,D36) -> 6178260 | E77: =SUM(E36,E68) -> 5606145 | F77: =SUM(F36,F68) -> 4935797 | G77: =SUM(G36,G68) -> 3857773 | H77: =SUM(H36,H68) -> 2480297 | I77: =SUM(I36,I68) -> 2299437 | J77: =J36+J68 -> 2240234
B84: .

Sheet DRE
A1: Demonstração do Resultado do Exercício - Análise Horizontal (ANO BASE 2017)
A2: Código da Conta | B2: Descrição da Conta | C2: 2024 | D2: 2023 | E2: 2022 | F2: 2021 | G2: 2020 | H2: 2019 | I2: 2018 | J2: 2017
A3: 3.01 | B3: Receita de Venda de Bens e/ou Serviços | C3: 3688326 | D3: 3926631 | E3: 4993235 | F3: 3365487 | G3: 2192173 | H3: 1915308 | I3: 1890654 | J3: 1913608
A4: 3.02 | B4: Custo dos Bens e/ou Serviços Vendidos | C4: -2764289 | D4: -2864102 | E4: -3796478 | F4: -2596881 | G4: -1743427 | H4: -1435200 | I4: -1436949 | J4: -1420259
A5: 3.03 | B5: Resultado Bruto | C5: 924037 | D5: 1062529 | E5: 1196757 | F5: 768606 | G5: 448746 | H5: 480108 | I5: 453705 | J5: 493349
B6: Margem Bruta | C6: =C5/C3 -> 0.25053019 | D6: =D5/D3 -> 0.27059558 | E6: =E5/E3 -> 0.23967568 | F6: =F5/F3 -> 0.22837883 | G6: =G5/G3 -> 0.20470373 | H6: =H5/H3 -> 0.25066882 | I6: =I5/I3 -> 0.23997252 | J6: =J5/J3 -> 0.2578109
A7: 3.04 | B7: Despesas/Receitas Operacionais | C7: -614527 | D7: -553952 | E7: -571662 | F7: -465457 | G7: -171070 | H7: -381253 | I7: -378691 | J7: -454272
B8: %Receita Líquida | D8: =D7/D3 -> -0.14107564 | E8: =E7/E3 -> -0.1144873 | F8: =F7/F3 -> -0.13830302 | G8: =G7/G3 -> -0.078036724 | H8: =H7/H3 -> -0.19905571 | I8: =I7/I3 -> -0.2002963 | J8: =J7/J3 -> -0.23739031
A9: 3.04.01 | B9: Despesas com Vendas | C9: -436329 | D9: -496236 | E9: -540264 | F9: -363763 | G9: -310653 | H9: -273006 | I9: -276226 | J9: -332140
A10: 3.04.02 | B10: Despesas Gerais e Administrativas | C10: 220817 | D10: -216172 | E10: -197325 | F10: -163437 | G10: -82691 | H10: -112095 | I10: -105148 | J10: -98920
A11: 3.04.03 | B11: Perdas pela Não Recuperabilidade de Ativos | C11: 0 | D11: 0 | E11: 0 | F11: 0 | G11: 0 | H11: 0 | I11: 0 | J11: 0
A12: 3.04.04 | B12: Outras Receitas Operacionais | C12: 50284 | D12: 165013 | E12: 174197 | F12: 57585 | G12: 221150 | H12: 5896 | I12: 5610 | J12: 0
A13: 3.04.06 | B13: Resultado de Equivalência Patrimonial | C13: -7665 | D13: -6557 | E13: -8270 | F13: 4158 | G13: 1124 | H13: -2048 | I13: -2927 | J13: -6125
A14: 3.05 | B14: Resultado Antes do Resultado Financeiro e dos Tributos | C14: 309510 | D14: 508577 | E14: 625095 | F14: 303149 | G14: 277676 | H14: 98855 | I14: 75014 | J14: 39077
A15: 3.06 | B15: Resultado Financeiro | C15: -207374 | D15: -254426 | E15: -31811 | F15: -94912 | G15: -5287 | H15: -70575 | I15: -64781 | J15: -83064
A16: 3.06.01 | B16: Receitas Financeiras | C16: 114170 | D16: 104320 | E16: 39509 | F16: 63856 | G16: 95289 | H16: 37406 | I16: 48130 | J16: 65135
A17: 3.06.02 | B17: Despesas Financeiras | C17: -321544 | D17: 104320 | E17: 86350 | F17: 43706 | G17: 59756 | H17: 32306 | I17: 48130 | J17: 65135
A18: 3.07 | B18: Resultado Antes dos Tributos sobre o Lucro | C18: 102136 | D18: 254151 | E18: 306984 | F18: 208237 | G18: 272389 | H18: 28280 | I18: 10233 | J18: -43987
A19: 3.08 | B19: Imposto de Renda e Contribuição Social sobre o Lucro | C19: -17098 | D19: -3269 | E19: -627 | F19: -5341 | G19: -76547 | H19: -7432 | I19: -10694 | J19: -3564
A20: 3.09 | B20: Resultado Líquido das Operações Continuadas | C20: 85038 | D20: 250882 | E20: 306357 | F20: 202896 | G20: 195842 | H20: 20848 | I20: -461 | J20: -47551
... A22: 3.11.01 | B22: Atribuído a Sócios da Empresa Controladora | C22: 80378 | D22: 246760 | E22: 303117 | F22: 200258 | G22: 190971 | H22: 16459 | I22: -461 | J22: -47551
A23: 3.99 | B23: Lucro por Ação - (Reais / Ação) | C23: 0.00000
A24: 3.99.01 | B24: Lucro Básico por Ação | C24: 0.00000
A25: 3.99.01.01 | B25: ON | D25: 1.7617 | E25: 2.1673 | F25: 1.4287 | G25: 1.4024
A26: 3.99.02 | B26: Lucro Diluído por Ação | C26: 0.57450
A27: 3.99.02.01 | B27: ON | C27: 0.57390 | D27: 1.7583 | E27: 2.1638 | F27: 1.4234 | G27: 1.4005

Sheet DFC
A1: Demonstração de Fluxo de Caixa (Método Indireto - Reais Mil) - Analise Vertical
A2: Código da Conta | B2: Descrição da Conta | C2: 2024 | D2: 2023 | E2: 2022 | F2: 2021 | G2: 2020 | H2: 2019 | I2: 2018 | J2: 2017
A3: 6.01 | B3: Caixa Líquido Atividades Operacionais | C3: 529080 | D3: 540734 | E3: -329969 | F3: -145748 | G3: -223656 | H3: -3671 | I3: -64563 | J3: 112580
A4: 6.01.01 | B4: Caixa Gerado nas Operações | C4: 314101 | D4: 538204 | E4: 601369 | F4: 355087 | G4: 207768 | H4: 128411 | I4: 101775 | J4: 21794
A5: 6.01.01.01 | B5: Lucro Líquido do Período | C5: 85038 | D5: 250882 | E5: 306357 | F5: 202896 | G5: 195842 | H5: 20848 | I5: -461 | J5: -47551
A6: 6.01.01.02 | B6: Depreciação e Amortização | C6: 57417 | D6: 56230 | E6: 49891 | F6: 42344 | G6: 46102 | H6: 35995 | I6: 32586 | J6: 31999
A7: 6.01.01.03 | B7: Equivalência Patrimonial | C7: 7665 | D7: 6557 | E7: 8270 | F7: -4158 | G7: -1124 | H7: 2048 | I7: 2927 | J7: 6125
A8: 6.01.01.04 | B8: Ganho no Valor Justo e Ajuste a Valor Presente | C8: -26243 | D8: -44979 | E8: -155260 | F8: -35656 | G8: -23551 | H8: -8549 | I8: 13083 | J8: -38532
A9: 6.01.01.05 | B9: Provisão (Reversão) para Riscos Tributários, Trabalhistas e Cíveis | C9: 156059 | D9: 7714 | E9: 11645 | F9: 11488 | G9: 4717 | H9: -1868 | I9: -1419 | J9: -1064
A10: 6.01.01.06 | B10: Provisão para Créditos de Liquidação Duvidosa | C10: -1078 | D10: 7655 | E10: 50824 | F10: 7401 | G10: 11252 | H10: 2582 | I10: 7045 | J10: 7923
A11: 6.01.01.07 | B11: Provisão (Reversão) para Perdas em Estoques | C11: 9124 | D11: -2433 | E11: 30934 | F11: 20827 | G11: 23802 | H11: -1867 | I11: 1266 | J11: 15457
A12: 6.01..01.08 | B12: Provisão e Receitas Diferidas | C12: -26017 | D12: 23175 | E12: 28996 | F12: 41884 | G12: 71107 | H12: 0 | I12: 0 | J12: 0
A13: 6.01.01.09 | B13: Stock Options | C13: 1071 | D13: 1882 | E13: 1299 | F13: 1475 | G13: 431 | H13: 425 | I13: 675 | J13: 316
... A56: 6.05.02 | B56: Saldo Final de Caixa e Equivalentes | C56: 566929 | D56: 591375 | E56: 426576 | F56: 359007 | G56: 544162 | H56: 460714 | I56: 393348 | J56: 387826

Sheet DFC - AH E AV
A1: Demonstração de Fluxo de Caixa (Método Indireto - Reais Mil) - Analise Horizontal e Vertical
A2: Código da Conta | B2: Descrição da Conta | C2: 2024 | D2: AH24 | E2: AV24 | F2: 2023 | G2: AH23 | H2: AV23 | I2: 2022 | J2: AH22 | K2: AV22 | L2: 2021 | M2: AH21 | N2: AV21 | O2: 2020 | P2: AH20 | Q2: AV20 | R2: 2019 | S2: AH19 | T2: AV19 | U2: 2018 | V2: AH18 | W2: AV18 | X2: 2017 | Y2: AH17 | Z2: AV17
A3: 6.01 | B3: Caixa Líquido Atividades Operacionais | C3: 529080 | D3: =(C3/X3)*Y3 -> 469.95914 | E3: =C3/$C$3 -> 1 | F3: 540734 | G3: =(F3/X3)*Y3 -> 480.31089 | H3: =F3/$F$3 -> 1 | I3: -329969 | J3: =(I3/X3)*Y3 -> -293.09735 | K3: =I3/$I$3 -> 1 | L3: -145748 | M3: =(L3/X3)*Y3 -> -129.46172 | N3: =L3/$L$3 -> 1 | O3: -223656 | P3: =(O3/X3)*Y3 -> -198.66406 | Q3: =O3/$O$3 -> 1 | R3: -3671 | S3: =(R3/X3)*Y3 -> -3.2607923 | T3: =R3/$R$3 -> 1 | U3: -64563 | V3: =(U3/X3)*Y3 -> -57.348552 | W3: =U3/$U$3 -> 1 | X3: 112580 | Y3: 100 | Z3: =X3/$X$3 -> 1
A4: 6.01.01 | B4: Caixa Gerado nas Operações | C4: 314101 | D4: =(C4/X4)*Y4 -> 1441.2269 | E4: =C4/$C$3 -> 0.59367392 | F4: 538204 | G4: =(F4/X4)*Y4 -> 2469.5054 | H4: =F4/$F$3 -> 0.99532117 | I4: 601369 | J4: =(I4/X4)*Y4 -> 2759.3328 | K4: =I4/$I$3 -> -1.8225015 | L4: 355087 | M4: =(L4/X4)*Y4 -> 1629.2879 | N4: =L4/$L$3 -> -2.4363079 | O4: 207768 | P4: =(O4/X4)*Y4 -> 953.3266 | Q4: =O4/$O$3 -> -0.92896234 | R4: 128411 | S4: =(R4/X4)*Y4 -> 589.20345 | T4: =R4/$R$3 -> -34.979842 | U4: 101775 | V4: =(U4/X4)*Y4 -> 466.98633 | W4: =U4/$U$3 -> -1.5763673 | X4: 21794 | Y4: 100 | Z4: =X4/$X$3 -> 0.19358678
A5: 6.01.01.01 | B5: Lucro Líquido do Período | C5: 85038 | D5: =(C5/X5)*Y5 -> -178.83536 | E5: =C5/$C$3 -> 0.16072806 | F5: 250882 | G5: =(F5/X5)*Y5 -> -527.60615 | H5: =F5/$F$3 -> 0.46396565 | I5: 306357 | J5: =(I5/X5)*Y5 -> -644.27036 | K5: =I5/$I$3 -> -0.92844176 | L5: 202896 | M5: =(L5/X5)*Y5 -> -426.69134 | N5: =L5/$L$3 -> -1.3921014 | O5: 195842 | P5: =(O5/X5)*Y5 -> -411.85674 | Q5: =O5/$O$3 -> -0.87563937 | R5: 20848 | S5: =(R5/X5)*Y5 -> -43.843452 | T5: =R5/$R$3 -> -5.6791065 | U5: -461 | V5: =(U5/X5)*Y5 -> 0.96948539 | W5: =U5/$U$3 -> 0.0071403126 | X5: -47551 | Y5: 100 | Z5: =X5/$X$3 -> -0.4223752
A6: 6.01.01.02 | B6: Depreciação e Amortização | C6: 57417 | D6: =(C6/X6)*Y6 -> 179.43373 | E6: =C6/$C$3 -> 0.10852234 | F6: 56230 | G6: =(F6/X6)*Y6 -> 175.72424 | H6: =F6/$F$3 -> 0.10398828 | I6: 49891 | J6: =(I6/X6)*Y6 -> 155.91425 | K6: =I6/$I$3 -> -0.15119905 | L6: 42344 | M6: =(L6/X6)*Y6 -> 132.32914 | N6: =L6/$L$3 -> -0.29052886 | O6: 46102 | P6: =(O6/X6)*Y6 -> 144.07325 | Q6: =O6/$O$3 -> -0.20612906 | R6: 35995 | S6: =(R6/X6)*Y6 -> 112.48789 | T6: =R6/$R$3 -> -9.8052302 | U6: 32586 | V6: =(U6/X6)*Y6 -> 101.83443 | W6: =U6/$U$3 -> -0.50471632 | X6: 31999 | Y6: 100 | Z6: =X6/$X$3 -> 0.28423343
A7: 6.01.01.03 | B7: Equivalência Patrimonial | C7: 7665 | D7: =(C7/X7)*Y7 -> 125.14286 | E7: =C7/$C$3 -> 0.014487412 | F7: 6557 | G7: =(F7/X7)*Y7 -> 107.05306 | H7: =F7/$F$3 -> 0.01212611 | I7: 8270 | J7: =(I7/X7)*Y7 -> 135.02041 | K7: =I7/$I$3 -> -0.02506296 | L7: -4158 | M7: =(L7/X7)*Y7 -> -67.885714 | N7: =L7/$L$3 -> 0.028528693 | O7: -1124 | P7: =(O7/X7)*Y7 -> -18.35102 | Q7: =O7/$O$3 -> 0.005025575 | R7: 2048 | S7: =(R7/X7)*Y7 -> 33.436735 | T7: =R7/$R$3 -> -0.55788613 | U7: 2927 | V7: =(U7/X7)*Y7 -> 47.787755 | W7: =U7/$U$3 -> -0.045335564 | X7: 6125 | Y7: 100 | Z7: =X7/$X$3 -> 0.054405756
A8: 6.01.01.04 | B8: Ganho no Valor Justo e Ajuste a Valor Presente | C8: -26243 | D8: =(C8/X8)*Y8 -> 68.107028 | E8: =C8/$C$3 -> -0.049601195 | F8: -44979 | G8: =(F8/X8)*Y8 -> 116.73155 | H8: =F8/$F$3 -> -0.083181379 | I8: -155260 | J8: =(I8/X8)*Y8 -> 402.93782 | K8: =I8/$I$3 -> 0.47052905 | L8: -35656 | M8: =(L8/X8)*Y8 -> 92.536074 | N8: =L8/$L$3 -> 0.24464144 | O8: -23551 | P8: =(O8/X8)*Y8 -> 61.120627 | Q8: =O8/$O$3 -> 0.1053001 | R8: -8549 | S8: =(R8/X8)*Y8 -> 22.186754 | T8: =R8/$R$3 -> 2.3287932 | U8: 13083 | V8: =(U8/X8)*Y8 -> -33.953597 | W8: =U8/$U$3 -> -0.20263928 | X8: -38532 | Y8: 100 | Z8: =X8/$X$3 -> -0.34226328
A9: 6.01.01.05 | B9: Provisão (Reversão) para Riscos Tributários, Trabalhistas e Cíveis | C9: 156059 | D9: =(C9/X9)*Y9 -> -14667.199 | E9: =C9/$C$3 -> 0.29496295 | F9: 7714 | G9: =(F9/X9)*Y9 -> -725 | H9: =F9/$F$3 -> 0.014265794 | I9: 11645 | J9: =(I9/X9)*Y9 -> -1094.4549 | K9: =I9/$I$3 -> -0.035291194 | L9: 11488 | M9: =(L9/X9)*Y9 -> -1079.6992 | N9: =L9/$L$3 -> -0.078820979 | O9: 4717 | P9: =(O9/X9)*Y9 -> -443.32707 | Q9: =O9/$O$3 -> -0.021090425 | R9: -1868 | S9: =(R9/X9)*Y9 -> 175.56391 | T9: =R9/$R$3 -> 0.50885317 | U9: -1419 | V9: =(U9/X9)*Y9 -> 133.36466 | W9: =U9/$U$3 -> 0.021978533 | X9: -1064 | Y9: 100 | Z9: =X9/$X$3 -> -0.009451057
A10: 6.01.01.06 | B10: Provisão para Créditos de Liquidação Duvidosa | C10: -1078 | D10: =(C10/X10)*Y10 -> -13.605957 | E10: =C10/$C$3 -> -0.0020374991 | F10: 7655 | G10: =(F10/X10)*Y10 -> 96.617443 | H10: =F10/$F$3 -> 0.014156683 | I10: 50824 | J10: =(I10/X10)*Y10 -> 641.47419 | K10: =I10/$I$3 -> -0.15402659 | L10: 7401 | M10: =(L10/X10)*Y10 -> 93.411587 | N10: =L10/$L$3 -> -0.050779428 | O10: 11252 | P10: =(O10/X10)*Y10 -> 142.01691 | Q10: =O10/$O$3 -> -0.050309404 | R10: 2582 | S10: =(R10/X10)*Y10 -> 32.588666 | T10: =R10/$R$3 -> -0.70335059 | U10: 7045 | V10: =(U10/X10)*Y10 -> 88.918339 | W10: =U10/$U$3 -> -0.10911823 | X10: 7923 | Y10: 100 | Z10: =X10/$X$3 -> 0.070376621
A11: 6.01.01.07 | B11: Provisão (Reversão) para Perdas em Estoques | C11: 9124 | D11: =(C11/X11)*Y11 -> 59.028272 | E11: =C11/$C$3 -> 0.017245029 | F11: -2433 | G11: =(F11/X11)*Y11 -> -15.740441 | H11: =F11/$F$3 -> -0.0044994397 | I11: 30934 | J11: =(I11/X11)*Y11 -> 200.12939 | K11: =I11/$I$3 -> -0.093748201 | L11: 20827 | M11: =(L11/X11)*Y11 -> 134.74154 | N11: =L11/$L$3 -> -0.14289733 | O11: 23802 | P11: =(O11/X11)*Y11 -> 153.98848 | Q11: =O11/$O$3 -> -0.10642236 | R11: -1867 | S11: =(R11/X11)*Y11 -> -12.07867 | T11: =R11/$R$3 -> 0.50858077 | U11: 1266 | V11: =(U11/X11)*Y11 -> 8.1904639 | W11: =U11/$U$3 -> -0.019608754 | X11: 15457 | Y11: 100 | Z11: =X11/$X$3 -> 0.13729792
A12: 6.01..01.08 | B12: Provisão e Receitas Diferidas | C12: -26017 | E12: =C12/$C$3 -> -0.049174038 | F12: 23175 | H12: =F12/$F$3 -> 0.042858411 | I12: 28996 | K12: =I12/$I$3 -> -0.087874922 | L12: 41884 | N12: =L12/$L$3 -> -0.28737273 | O12: 71107 | Q12: =O12/$O$3 -> -0.31793021 | R12: 0 | T12: =R12/$R$3 -> 0 | U12: 0 | W12: =U12/$U$3 -> 0 | X12: 0 | Y12: 100 | Z12: =X12/$X$3 -> 0
A13: 6.01.01.09 | B13: Stock Options | C13: 1071 | D13: =(C13/X13)*Y13 -> 338.92405 | E13: =C13/$C$3 -> 0.0020242685 | F13: 1882 | G13: =(F13/X13)*Y13 -> 595.56962 | H13: =F13/$F$3 -> 0.0034804543 | I13: 1299 | J13: =(I13/X13)*Y13 -> 411.07595 | K13: =I13/$I$3 -> -0.0039367335 | L13: 1475 | M13: =(L13/X13)*Y13 -> 466.77215 | N13: =L13/$L$3 -> -0.010120207 | O13: 431 | P13: =(O13/X13)*Y13 -> 136.39241 | Q13: =O13/$O$3 -> -0.0019270666 | R13: 425 | S13: =(R13/X13)*Y13 -> 134.49367 | T13: =R13/$R$3 -> -0.11577227 | U13: 675 | V13: =(U13/X13)*Y13 -> 213.60759 | W13: =U13/$U$3 -> -0.010454905 | X13: 316 | Y13: 100 | Z13: =X13/$X$3 -> 0.0028068929
A14: 6.01.01.10 | B14: Encargos Sobre Empréstimos e Contratos de Arrendamento | C14: 165561 | D14: =(C14/X14)*Y14 -> 212.45653 | E14: =C14/$C$3 -> 0.31292243 | F14: 235958 | G14: =(F14/X14)*Y14 -> 302.79364 | H14: =F14/$F$3 -> 0.43636612 | I14: 271262 | J14: =(I14/X14)*Y14 -> 348.09758 | K14: =I14/$I$3 -> -0.82208329 | L14: 89200 | M14: =(L14/X14)*Y14 -> 114.4661 | N14: =L14/$L$3 -> -0.61201526 | O14: 61796 | P14: =(O14/X14)*Y14 -> 79.299858 | Q14: =O14/$O$3 -> -0.27629932 | R14: 71813 | S14: =(R14/X14)*Y14 -> 92.154196 | T14: =R14/$R$3 -> -19.562245 | U14: 57138 | V14: =(U14/X14)*Y14 -> 73.322468 | W14: =U14/$U$3 -> -0.88499605 | X14: 77927 | Y14: 100 | Z14: =X14/$X$3 -> 0.69219222
A15: 6.01.01.11 | B15: Variação Cambial | C15: 29622 | D15: =(C15/X15)*Y15 -> -86.185627 | E15: =C15/$C$3 -> 0.055987752 | F15: -5380 | G15: =(F15/X15)*Y15 -> 15.653186 | H15: =F15/$F$3 -> -0.0099494391 | I15: 6129 | J15: =(I15/X15)*Y15 -> -17.832412 | K15: =I15/$I$3 -> -0.018574472 | L15: 6743 | M15: =(L15/X15)*Y15 -> -19.618854 | N15: =L15/$L$3 -> -0.046264786 | O15: -5967 | P15: =(O15/X15)*Y15 -> 17.361071 | Q15: =O15/$O$3 -> 0.026679365 | R15: -5384 | S15: =(R15/X15)*Y15 -> 15.664824 | T15: =R15/$R$3 -> 1.4666303 | U15: -17204 | V15: =(U15/X15)*Y15 -> 50.055281 | W15: =U15/$U$3 -> 0.26646841 | X15: -34370 | Y15: 100 | Z15: =X15/$X$3 -> -0.30529401
A16: 6.01.01.12 | B16: Juros Sobre Impostos e Atualização Monetária | C16: 5607 | E16: =C16/$C$3 -> 0.010597641 | F16: -2326 | H16: =F16/$F$3 -> -0.0043015605 | I16: -9605 | K16: =I16/$I$3 -> 0.029108795 | L16: -16506 | N16: =L16/$L$3 -> 0.11325027 | O16: -31810 | Q16: =O16/$O$3 -> 0.14222735 | R16: -3403 | T16: =R16/$R$3 -> 0.92699537 | U16: -4555 | W16: =U16/$U$3 -> 0.070551245 | X16: 0 | Y16: 100 | Z16: =X16/$X$3 -> 0
A17: 6.01.01.13 | B17: Ganhos (Perdas) em Processos Administrativos e Judiciais | C17: 0 | E17: =C17/$C$3 -> 0 | F17: 0 | H17: =F17/$F$3 -> 0 | I17: 0 | K17: =I17/$I$3 -> 0 | L17: -14734 | N17: =L17/$L$3 -> 0.1010923 | O17: -221376 | Q17: =O17/$O$3 -> 0.98980577 | R17: 0 | T17: =R17/$R$3 -> 0 | U17: 0 | W17: =U17/$U$3 -> 0 | X17: 0 | Y17: 100 | Z17: =X17/$X$3 -> 0
A18: 6.01.01.14 | B18: Imposto de Renda e Contribuição Social (Corrente e Diferido) | C18: 17098 | E18: =C18/$C$3 -> 0.032316474 | F18: 3269 | H18: =F18/$F$3 -> 0.0060454863 | I18: 627 | K18: =I18/$I$3 -> -0.0019001785 | L18: 5341 | N18: =L18/$L$3 -> -0.036645443 | O18: 76547 | Q18: =O18/$O$3 -> -0.34225328 | R18: 7432 | T18: =R18/$R$3 -> -2.0245165 | U18: 10694 | W18: =U18/$U$3 -> -0.16563666 | X18: 0 | Y18: 100 | Z18: =X18/$X$3 -> 0
A19: 6.01.01.15 | B19: Ganho na Alienação de Imobilizados | C19: 0 | E19: =C19/$C$3 -> 0 | F19: 0 | H19: =F19/$F$3 -> 0 | I19: 0 | K19: =I19/$I$3 -> 0 | L19: -3458 | N19: =L19/$L$3 -> 0.023725883 | O19: 0 | Q19: =O19/$O$3 -> 0 | R19: 0 | T19: =R19/$R$3 -> 0 | U19: 0 | W19: =U19/$U$3 -> 0 | X19: 0 | Y19: 100 | Z19: =X19/$X$3 -> 0
A20: 6.01.02 | B20: Variações nos Ativos e Passivos | C20: 214979 | D20: =(C20/X20)*Y20 -> 236.79752 | E20: =C20/$C$3 -> 0.40632608 | F20: 2530 | G20: =(F20/X20)*Y20 -> 2.7867733 | H20: =F20/$F$3 -> 0.0046788254 | I20: -931338 | J20: =(I20/X20)*Y20 -> -1025.8608 | K20: =I20/$I$3 -> 2.8225015 | L20: -500835 | M20: =(L20/X20)*Y20 -> -551.66546 | N20: =L20/$L$3 -> 3.4363079 | O20: -431424 | P20: =(O20/X20)*Y20 -> -475.20983 | Q20: =O20/$O$3 -> 1.9289623 | R20: -132082 | S20: =(R20/X20)*Y20 -> -145.48719 | T20: =R20/$R$3 -> 35.979842 | U20: -166338 | V20: =(U20/X20)*Y20 -> -183.21988 | W20: =U20/$U$3 -> 2.5763673 | X20: 90786 | Y20: 100 | Z20: =X20/$X$3 -> 0.80641322
A21: 6.01.02.01 | B21: Contas a Receber | C21: 441827 | D21: =(C21/X21)*Y21 -> 3974.3366 | E21: =C21/$C$3 -> 0.83508543 | F21: -200525 | G21: =(F21/X21)*Y21 -> -1803.769 | H21: =F21/$F$3 -> -0.37083853 | I21: -441003 | J21: =(I21/X21)*Y21 -> -3966.9245 | K21: =I21/$I$3 -> 1.3364983 | L21: -74514 | M21: =(L21/X21)*Y21 -> -670.27076 | N21: =L21/$L$3 -> 0.5112523 | O21: -451149 | P21: =(O21/X21)*Y21 -> -4058.1902 | Q21: =O21/$O$3 -> 2.0171558 | R21: -25435 | S21: =(R21/X21)*Y21 -> -228.79374 | T21: =R21/$R$3 -> 6.9286298 | U21: 58353 | V21: =(U21/X21)*Y21 -> 524.8988 | W21: =U21/$U$3 -> -0.90381488 | X21: 11117 | Y21: 100 | Z21: =X21/$X$3 -> 0.098747557
A22: 6.01.02.02 | B22: Estoques | C22: 152343 | D22: =(C22/X22)*Y22 -> -224.91695 | E22: =C22/$C$3 -> 0.28793944 | F22: 148528 | G22: =(F22/X22)*Y22 -> -219.28454 | H22: =F22/$F$3 -> 0.27467849 | I22: 265514 | J22: =(I22/X22)*Y22 -> -392.00094 | K22: =I22/$I$3 -> -0.80466347 | L22: -1061553 | M22: =(L22/X22)*Y22 -> 1567.2612 | N22: =L22/$L$3 -> 7.2834824 | O22: -190753 | P22: =(O22/X22)*Y22 -> 281.62491 | Q22: =O22/$O$3 -> 0.85288568 | R22: 22777 | S22: =(R22/X22)*Y22 -> -33.627626 | T22: =R22/$R$3 -> -6.2045764 | U22: -63200 | V22: =(U22/X22)*Y22 -> 93.307546 | W22: =U22/$U$3 -> 0.97888884 | X22: -67733 | Y22: 100 | Z22: =X22/$X$3 -> -0.60164328
A23: 6.01.02.03 | B23: Imposto a Recuperar | C23: -30560 | D23: =(C23/X23)*Y23 -> -140.24138 | E23: =C23/$C$3 -> -0.057760641 | F23: -104020 | G23: =(F23/X23)*Y23 -> -477.35304 | H23: =F23/$F$3 -> -0.19236815 | I23: -206173 | J23: =(I23/X23)*Y23 -> -946.13831 | K23: =I23/$I$3 -> 0.62482536 | L23: 69167 | M23: =(L23/X23)*Y23 -> 317.41086 | N23: =L23/$L$3 -> -0.47456569 | O23: -37104 | P23: =(O23/X23)*Y23 -> -170.27213 | Q23: =O23/$O$3 -> 0.16589763 | R23: -8262 | S23: =(R23/X23)*Y23 -> -37.914735 | T23: =R23/$R$3 -> 2.2506129 | U23: 8497 | V23: =(U23/X23)*Y23 -> 38.993162 | W23: =U23/$U$3 -> -0.13160789 | X23: 21791 | Y23: 100 | Z23: =X23/$X$3 -> 0.19356014
A24: 6.01.02.04 | B24: Adiantamentos Diversos | C24: 15713 | D24: =(C24/X24)*Y24 -> -221.96638 | E24: =C24/$C$3 -> 0.029698722 | F24: -5607 | G24: =(F24/X24)*Y24 -> 79.206103 | H24: =F24/$F$3 -> -0.010369239 | I24: 6075 | J24: =(I24/X24)*Y24 -> -85.817206 | K24: =I24/$I$3 -> -0.01841082 | L24: -7860 | M24: =(L24/X24)*Y24 -> 111.03263 | N24: =L24/$L$3 -> 0.053928699 | O24: 15790 | P24: =(O24/X24)*Y24 -> -223.0541 | Q24: =O24/$O$3 -> -0.070599492 | R24: 4100 | S24: =(R24/X24)*Y24 -> -57.917785 | T24: =R24/$R$3 -> -1.1168619 | U24: -20053 | V24: =(U24/X24)*Y24 -> 283.27447 | W24: =U24/$U$3 -> 0.31059585 | X24: -7079 | Y24: 100 | Z24: =X24/$X$3 -> -0.06287973
A25: 6.01.02.05 | B25: Contas a Receber de Partes Relacionadas | C25: -1532 | E25: =C25/$C$3 -> -0.0028955923 | F25: 442 | H25: =F25/$F$3 -> 0.00081740745 | I25: 704 | K25: =I25/$I$3 -> -0.0021335338 | L25: 9904 | N25: =L25/$L$3 -> -0.067952905 | O25: 15296 | Q25: =O25/$O$3 -> -0.068390743 | R25: 0 | T25: =R25/$R$3 -> 0 | U25: 0 | W25: =U25/$U$3 -> 0 | X25: 0 | Y25: 100 | Z25: =X25/$X$3 -> 0
A26: 6.01.02.06 | B26: Outros Créditos | C26: 18047 | D26: =(C26/X26)*Y26 -> 1180.3139 | E26: =C26/$C$3 -> 0.034110153 | F26: 74404 | G26: =(F26/X26)*Y26 -> 4866.1871 | H26: =F26/$F$3 -> 0.13759815 | I26: 12900 | J26: =(I26/X26)*Y26 -> 843.68869 | K26: =I26/$I$3 -> -0.039094582 | L26: -19615 | M26: =(L26/X26)*Y26 -> -1282.8646 | N26: =L26/$L$3 -> 0.13458161 | O26: 15352 | P26: =(O26/X26)*Y26 -> 1004.0549 | Q26: =O26/$O$3 -> -0.068641127 | R26: -21639 | S26: =(R26/X26)*Y26 -> -1415.2387 | T26: =R26/$R$3 -> 5.8945791 | U26: -49586 | V26: =(U26/X26)*Y26 -> -3243.0347 | W26: =U26/$U$3 -> 0.76802503 | X26: 1529 | Y26: 100 | Z26: =X26/$X$3 -> 0.013581453
A27: 6.01.02.07 | B27: Fornecedores | C27: -207637 | D27: =(C27/X27)*Y27 -> -158.59959 | E27: =C27/$C$3 -> -0.39244916 | F27: 218471 | G27: =(F27/X27)*Y27 -> 166.87494 | H27: =F27/$F$3 -> 0.40402675 | I27: -601854 | J27: =(I27/X27)*Y27 -> -459.71479 | K27: =I27/$I$3 -> 1.8239713 | L27: 659992 | M27: =(L27/X27)*Y27 -> 504.1224 | N27: =L27/$L$3 -> -4.5283091 | O27: 178231 | P27: =(O27/X27)*Y27 -> 136.13838 | Q27: =O27/$O$3 -> -0.79689791 | R27: -56863 | S27: =(R27/X27)*Y27 -> -43.433726 | T27: =R27/$R$3 -> 15.489785 | U27: -18115 | V27: =(U27/X27)*Y27 -> -13.8368 | W27: =U27/$U$3 -> 0.28057866 | X27: 130919 | Y27: 100 | Z27: =X27/$X$3 -> 1.1628975
A28: 6.01.02.08 | B28: Obrigações Tributarias | C28: 20966 | D28: =(C28/X28)*Y28 -> 81.19433 | E28: =C28/$C$3 -> 0.039627278 | F28: 42891 | G28: =(F28/X28)*Y28 -> 166.10255 | H28: =F28/$F$3 -> 0.079319961 | I28: 139992 | J28: =(I28/X28)*Y28 -> 542.14236 | K28: =I28/$I$3 -> -0.42425804 | L28: 20777 | M28: =(L28/X28)*Y28 -> 80.462396 | N28: =L28/$L$3 -> -0.14255427 | O28: 8002 | P28: =(O28/X28)*Y28 -> 30.989079 | Q28: =O28/$O$3 -> -0.035778159 | R28: -848 | S28: =(R28/X28)*Y28 -> -3.2840214 | T28: =R28/$R$3 -> 0.23099973 | U28: -24700 | V28: =(U28/X28)*Y28 -> -95.654868 | W28: =U28/$U$3 -> 0.38257206 | X28: 25822 | Y28: 100 | Z28: =X28/$X$3 -> 0.22936578
A29: 6.01.02.09 | B29: Outras Contas a Pagar | C29: 3086 | D29: =(C29/X29)*Y29 -> -101.04781 | E29: =C29/$C$3 -> 0.0058327663 | F29: -1687 | G29: =(F29/X29)*Y29 -> 55.239031 | H29: =F29/$F$3 -> -0.0031198334 | I29: -2674 | J29: =(I29/X29)*Y29 -> 87.557302 | K29: =I29/$I$3 -> 0.0081037916 | L29: -23041 | M29: =(L29/X29)*Y29 -> 754.45318 | N29: =L29/$L$3 -> 0.15808793 | O29: 55323 | P29: =(O29/X29)*Y29 -> -1811.4931 | Q29: =O29/$O$3 -> -0.24735755 | R29: -942 | S29: =(R29/X29)*Y29 -> 30.844794 | T29: =R29/$R$3 -> 0.25660583 | U29: 804 | V29: =(U29/X29)*Y29 -> -26.32613 | W29: =U29/$U$3 -> -0.012452953 | X29: -3054 | Y29: 100 | Z29: =X29/$X$3 -> -0.027127376
A30: 6.01.02.10 | B30: Contas a Pagar de Partes Relacionadas | C30: 193 | E30: =C30/$C$3 -> 0.00036478415 | F30: -128 | H30: =F30/$F$3 -> -0.00023671528 | I30: 0 | K30: =I30/$I$3 -> 0 | L30: 0 | N30: =L30/$L$3 -> 0 | O30: 0 | Q30: =O30/$O$3 -> 0 | R30: 0 | T30: =R30/$R$3 -> 0 | U30: 0 | W30: =U30/$U$3 -> 0 | X30: 0 | Y30: 100 | Z30: =X30/$X$3 -> 0
A31: 6.01.02.11 | B31: Pagamento de Juros Sobre Empréstimos e Contratos de Arrendamento | C31: -185862 | D31: =(C31/X31)*Y31 -> 522.62745 | E31: =C31/$C$3 -> -0.35129281 | F31: -162205 | G31: =(F31/X31)*Y31 -> 456.10607 | H31: =F31/$F$3 -> -0.29997189 | I31: -100278 | J31: =(I31/X31)*Y31 -> 281.97284 | K31: =I31/$I$3 -> 0.30390128 | L31: -68264 | M31: =(L31/X31)*Y31 -> 191.95231 | N31: =L31/$L$3 -> 0.46837006 | O31: -40412 | P31: =(O31/X31)*Y31 -> 113.63496 | Q31: =O31/$O$3 -> 0.1806882 | R31: -63766 | S31: =(R31/X31)*Y31 -> 179.30433 | T31: =R31/$R$3 -> 17.370199 | U31: -82795 | V31: =(U31/X31)*Y31 -> 232.81219 | W31: =U31/$U$3 -> 1.2823908 | X31: -35563 | Y31: 100 | Z31: =X31/$X$3 -> -0.31589092
A32: 6.01.02.12 | B32: Indenizações | C32: -11605 | E32: =C32/$C$3 -> -0.021934301 | F32: -8034 | H32: =F32/$F$3 -> -0.014857582 | I32: -4541 | K32: =I32/$I$3 -> 0.013761899 | L32: -5828 | N32: =L32/$L$3 -> 0.039986827 | O32: 0 | Q32: =O32/$O$3 -> 0 | R32: 0 | T32: =R32/$R$3 -> 0 | U32: 0 | W32: =U32/$U$3 -> 0 | X32: 0 | Y32: 100 | Z32: =X32/$X$3 -> 0
A33: 6.01.03 | B33: Outros | C33: 0 | E33: =C33/$C$3 -> 0 | F33: 0 | H33: =F33/$F$3 -> 0 | I33: 0 | K33: =I33/$I$3 -> 0 | L33: 0 | N33: =L33/$L$3 -> 0 | O33: 0 | Q33: =O33/$O$3 -> 0 | R33: 0 | T33: =R33/$R$3 -> 0 | U33: 0 | W33: =U33/$U$3 -> 0 | X33: 0 | Y33: 100 | Z33: =X33/$X$3 -> 0
A34: 6.02 | B34: Caixa Líquido Atividades de Investimento | C34: -286526 | D34: =(C34/X34)*Y34 -> 665.42651 | E34: =C34/$C$3 -> -0.54155515 | F34: -161297 | G34: =(F34/X34)*Y34 -> 374.59532 | H34: =F34/$F$3 -> -0.29829269 | I34: -155602 | J34: =(I34/X34)*Y34 -> 361.36928 | K34: =I34/$I$3 -> 0.47156551 | L34: -67034 | M34: =(L34/X34)*Y34 -> 155.67942 | N34: =L34/$L$3 -> 0.45993084 | O34: -43307 | P34: =(O34/X34)*Y34 -> 100.57595 | Q34: =O34/$O$3 -> 0.19363219 | R34: -31968 | S34: =(R34/X34)*Y34 -> 74.242319 | T34: =R34/$R$3 -> 8.7082539 | U34: -10853 | V34: =(U34/X34)*Y34 -> 25.204951 | W34: =U34/$U$3 -> 0.16809938 | X34: -43059 | Y34: 100 | Z34: =X34/$X$3 -> -0.38247468
A35: 6.02.01 | B35: Recebimento de Dividendos | C35: 0 | E35: =C35/$C$3 -> 0 | F35: 0 | H35: =F35/$F$3 -> 0 | I35: 0 | K35: =I35/$I$3 -> 0 | L35: 0 | N35: =L35/$L$3 -> 0 | O35: 0 | Q35: =O35/$O$3 -> 0 | R35: 0 | T35: =R35/$R$3 -> 0 | U35: 0 | W35: =U35/$U$3 -> 0 | X35: 0 | Y35: 100 | Z35: =X35/$X$3 -> 0
A36: 6.02.02 | B36: Integralização de Capital - Investida | C36: -23196 | E36: =C36/$C$3 -> -0.043842141 | F36: -68677 | H36: =F36/$F$3 -> -0.12700699 | I36: -72553 | K36: =I36/$I$3 -> 0.21987823 | L36: -13501 | N36: =L36/$L$3 -> 0.092632489 | O36: -12000 | Q36: =O36/$O$3 -> 0.053653826 | R36: -12600 | T36: =R36/$R$3 -> 3.4323073 | U36: 0 | W36: =U36/$U$3 -> 0 | X36: 0 | Y36: 100 | Z36: =X36/$X$3 -> 0
A37: 6.02.03 | B37: Aquisição de Investimento | C37: 0 | E37: =C37/$C$3 -> 0 | F37: 0 | H37: =F37/$F$3 -> 0 | I37: 0 | K37: =I37/$I$3 -> 0 | L37: 0 | N37: =L37/$L$3 -> 0 | O37: 0 | Q37: =O37/$O$3 -> 0 | R37: 0 | T37: =R37/$R$3 -> 0 | U37: 7673 | W37: =U37/$U$3 -> -0.11884516 | X37: 0 | Y37: 100 | Z37: =X37/$X$3 -> 0
A38: 6.02.04 | B38: Aquisição de Imobilizado | C38: -20886 | D38: =(C38/X38)*Y38 -> 132.53379 | E38: =C38/$C$3 -> -0.039476072 | F38: -49228 | G38: =(F38/X38)*Y38 -> 312.38023 | H38: =F38/$F$3 -> -0.091039217 | I38: -35286 | J38: =(I38/X38)*Y38 -> 223.91015 | K38: =I38/$I$3 -> 0.10693732 | L38: -27481 | M38: =(L38/X38)*Y38 -> 174.38289 | N38: =L38/$L$3 -> 0.18855147 | O38: -9186 | P38: =(O38/X38)*Y38 -> 58.290501 | Q38: =O38/$O$3 -> 0.041072003 | R38: -5078 | S38: =(R38/X38)*Y38 -> 32.222857 | T38: =R38/$R$3 -> 1.3832743 | U38: -4283 | V38: =(U38/X38)*Y38 -> 27.17812 | W38: =U38/$U$3 -> 0.066338305 | X38: -15759 | Y38: 100 | Z38: =X38/$X$3 -> -0.13998046
A39: 6.02.05 | B39: Aumento do Intangível | C39: -70198 | D39: =(C39/X39)*Y39 -> 257.13553 | E39: =C39/$C$3 -> -0.13267937 | F39: -36571 | G39: =(F39/X39)*Y39 -> 133.95971 | H39: =F39/$F$3 -> -0.067632144 | I39: -47763 | J39: =(I39/X39)*Y39 -> 174.95604 | K39: =I39/$I$3 -> 0.14474996 | L39: -16043 | M39: =(L39/X39)*Y39 -> 58.765568 | N39: =L39/$L$3 -> 0.11007355 | O39: -22121 | P39: =(O39/X39)*Y39 -> 81.029304 | Q39: =O39/$O$3 -> 0.098906356 | R39: -14290 | S39: =(R39/X39)*Y39 -> 52.344322 | T39: =R39/$R$3 -> 3.8926723 | U39: -14243 | V39: =(U39/X39)*Y39 -> 52.172161 | W39: =U39/$U$3 -> 0.22060623 | X39: -27300 | Y39: 100 | Z39: =X39/$X$3 -> -0.24249423
A40: 6.02.06 | B40: Pagamento por aquisição de contolada | C40: 0 | E40: =C40/$C$3 -> 0 | F40: -7229 | H40: =F40/$F$3 -> -0.013368865 | I40: 0 | K40: =I40/$I$3 -> 0 | L40: -10009 | N40: =L40/$L$3 -> 0.068673327 | O40: 0 | Q40: =O40/$O$3 -> 0 | R40: 0 | T40: =R40/$R$3 -> 0 | U40: 0 | W40: =U40/$U$3 -> 0 | X40: 0 | Y40: 100 | Z40: =X40/$X$3 -> 0
...

Sheet BP - AH e AV
A1: Balanço Patrimonial - Análise Vertical
A2: Código da Conta | B2: Descrição da Conta | C2: 2024 | D2: AH24 | E2: AV24 | F2: 2023 | G2: AH23 | H2: AV23 | I2: 2022 | J2: AH22 | K2: AV22 | L2: 2021 | M2: AH21 | N2: AV21 | O2: 2020 | P2: AH20 | Q2: AV20 | R2: 2019 | S2: AH19 | T2: AV19 | U2: 2018 | V2: AH18 | W2: AV18 | X2: 2017 | Y2: AH17 | Z2: AV18
A3: 1 | B3: Ativo Total | C3: 4466987 | D3: =(C3/X3)*Y3 -> 257.63266 | E3: =F3/F3 -> 1 | F3: 4581833 | G3: =(F$3/X3)*$Y3 -> 264.25638 | H3: =$I$3/$I$3 -> 1 | I3: 4199825 | J3: =(I$3/X3)*$Y3 -> 242.22414 | K3: =$L$3/$L$3 -> 1 | L3: 3754136 | M3: =(L$3/X3)*$Y3 -> 216.51911 | N3: =$L$3/$L$3 -> 1 | O3: 2824635 | P3: =(O$3/X3)*$Y3 -> 162.91031 | Q3: =$O$3/$O$3 -> 1 | R3: 1945403 | S3: =(R$3/X3)*$Y3 -> 112.20076 | T3: =$R$3/$R$3 -> 1 | U3: 1789529 | V3: =(U3/X3)*Y3 -> 103.21076 | W3: =$U$3/$U$3 -> 1 | X3: 1733859 | Y3: 100 | Z3: =X3/$X$3 -> 1
A4: 1.01 | B4: Ativo Circulante | C4: 2967747 | D4: =(C4/X4)*Y4 -> 210.27986 | E4: =C4/$C$3 -> 0.66437332 | F4: 3575173 | G4: =(F$3/X4)*$Y4 -> 324.64601 | H4: =$F4/$F$3 -> 0.78029317 | I4: 3430062 | J4: =(I$3/X4)*$Y4 -> 297.57881 | K4: =$I4/$I$3 -> 0.81671546 | L4: 3120040 | M4: =(L$3/X4)*$Y4 -> 265.9995 | N4: =$L4/$L$3 -> 0.83109403 | O4: 2211237 | P4: =(O$3/X4)*$Y4 -> 200.13966 | Q4: =$O4/$O$3 -> 0.78283991 | R4: 1471763 | S4: =(R$3/X4)*$Y4 -> 137.84163 | T4: =$R4/$R$3 -> 0.75653374 | U4: 1418740 | V4: =(U4/X4)*Y4 -> 100.52489 | W4: =$U4/$U$3 -> 0.79280079 | X4: 1411332 | Y4: 100 | Z4: =X4/$X$3 -> 0.81398314
A5: 1.01.01 | B5: Caixa e Equivalentes de Caixa | C5: 566929 | D5: =(C5/X5)*Y5 -> 146.18128 | E5: =C5/$C$3 -> 0.1269153 | F5: 591375 | G5: =(F$3/X5)*$Y5 -> 1181.4146 | H5: =$F5/$F$3 -> 0.12906952 | I5: 426576 | J5: =(I$3/X5)*$Y5 -> 1082.9148 | K5: =$I5/$I$3 -> 0.10156995 | L5: 359007 | M5: =(L$3/X5)*$Y5 -> 967.99493 | N5: =$L5/$L$3 -> 0.095629727 | O5: 544162 | P5: =(O$3/X5)*$Y5 -> 728.32533 | Q5: =$O5/$O$3 -> 0.19264861 | R5: 460714 | S5: =(R$3/X5)*$Y5 -> 501.61748 | T5: =$R5/$R$3 -> 0.23682188 | U5: 393348 | V5: =(U5/X5)*Y5 -> 101.42383 | W5: =$U5/$U$3 -> 0.21980532 | X5: 387826 | Y5: 100 | Z5: =X5/$X$3 -> 0.22367793
A6: 1.01.02 | B6: Aplicações Financeiras | C6: 0 | D6: 0 | E6: =C6/$C$3 -> 0 | F6: 0 | H6: =$F6/$F$3 -> 0 | I6: 0 | K6: =$I6/$I$3 -> 0 | L6: 0 | N6: =$L6/$L$3 -> 0 | O6: 0 | Q6: =$O6/$O$3 -> 0 | R6: 0 | T6: =$R6/$R$3 -> 0 | U6: 0 | W6: =$U6/$U$3 -> 0 | X6: 0 | Y6: 100 | Z6: =X6/$X$3 -> 0
A7: 1.01.03 | B7: Contas a Receber | C7: 860937 | D7: =(C7/X7)*Y7 -> 311.65592 | E7: =C7/$C$3 -> 0.19273327 | F7: 1326360 | G7: =(F$3/X7)*$Y7 -> 1658.6061 | H7: =$F7/$F$3 -> 0.2894824 | I7: 1132483 | J7: =(I$3/X7)*$Y7 -> 1520.3207 | K7: =$I7/$I$3 -> 0.26965004 | L7: 762625 | M7: =(L$3/X7)*$Y7 -> 1358.9829 | N7: =$L7/$L$3 -> 0.20314261 | O7: 698044 | P7: =(O$3/X7)*$Y7 -> 1022.5071 | Q7: =$O7/$O$3 -> 0.24712715 | R7: 258642 | S7: =(R$3/X7)*$Y7 -> 704.22848 | T7: =$R7/$R$3 -> 0.13295034 | U7: 235282 | V7: =(U7/X7)*Y7 -> 85.171188 | W7: =$U7/$U$3 -> 0.13147705 | X7: 276246 | Y7: 100 | Z7: =X7/$X$3 -> 0.15932437
A8: 1.01.04 | B8: Estoques | C8: 1096246 | D8: =(C8/X8)*Y8 -> 216.41887 | E8: =C8/$C$3 -> 0.24541061 | F8: 1256483 | G8: =(F$3/X8)*$Y8 -> 904.53706 | H8: =$F8/$F$3 -> 0.27423151 | I8: 1390723 | J8: =(I$3/X8)*$Y8 -> 829.12175 | K8: =$I8/$I$3 -> 0.33113832 | L8: 1690347 | M8: =(L$3/X8)*$Y8 -> 741.13464 | N8: =$L8/$L$3 -> 0.45026259 | O8: 645750 | P8: =(O$3/X8)*$Y8 -> 557.63426 | Q8: =$O8/$O$3 -> 0.22861361 | R8: 494422 | S8: =(R$3/X8)*$Y8 -> 384.05789 | T8: =$R8/$R$3 -> 0.25414888 | U8: 534726 | V8: =(U8/X8)*Y8 -> 105.56463 | W8: =$U8/$U$3 -> 0.29880823 | X8: 506539 | Y8: 100 | Z8: =X8/$X$3 -> 0.29214544
A9: 1.01.06 | B9: Tributos a Recuperar | C9: 301400 | D9: =(C9/X9)*Y9 -> 212.01761 | E9: =C9/$C$3 -> 0.067472773 | F9: 304370 | G9: =(F$3/X9)*$Y9 -> 3223.0567 | H9: =$F9/$F$3 -> 0.066429745 | I9: 361523 | J9: =(I$3/X9)*$Y9 -> 2954.336 | K9: =$I9/$I$3 -> 0.086080491 | L9: 176025 | M9: =(L$3/X9)*$Y9 -> 2640.8194 | N9: =$L9/$L$3 -> 0.046888285 | O9: 221036 | P9: =(O$3/X9)*$Y9 -> 1986.9687 | Q9: =$O9/$O$3 -> 0.078252942 | R9: 124615 | S9: =(R$3/X9)*$Y9 -> 1368.4794 | T9: =$R9/$R$3 -> 0.064056136 | U9: 129445 | V9: =(U9/X9)*Y9 -> 91.057134 | W9: =$U9/$U$3 -> 0.072334676 | X9: 142158 | Y9: 100 | Z9: =X9/$X$3 -> 0.081989366
A10: 1.01.06.01 | B10: Tributos Correntes a Recuperar | C10: 301400 | E10: =C10/$C$3 -> 0.067472773 | F10: 304370 | H10: =$F10/$F$3 -> 0.066429745 | I10: 361523 | K10: =$I10/$I$3 -> 0.086080491 | L10: 176025 | N10: =$L10/$L$3 -> 0.046888285 | O10: 221036 | Q10: =$O10/$O$3 -> 0.078252942 | R10: 124615 | T10: =$R10/$R$3 -> 0.064056136 | U10: 129445 | W10: =$U10/$U$3 -> 0.072334676 | X10: 0 | Y10: 100 | Z10: =X10/$X$3 -> 0
A11: 1.01.06.01.01 | B11: Tributos a Recuperar | C11: 200109 | E11: =C11/$C$3 -> 0.04479731 | F11: 210811 | H11: =$F11/$F$3 -> 0.046010188 | I11: 309169 | K11: =$I11/$I$3 -> 0.073614734 | L11: 157222 | N11: =$L11/$L$3 -> 0.041879676 | O11: 183356 | Q11: =$O11/$O$3 -> 0.064913166 | R11: 87826 | T11: =$R11/$R$3 -> 0.045145402 | U11: 101769 | W11: =$U11/$U$3 -> 0.056869154 | X11: 0 | Y11: 100 | Z11: =X11/$X$3 -> 0
A12: 1.01.06.01.02 | B12: Imposto de Renda e Contribuição Social a Recuperar | C12: 101291 | E12: =C12/$C$3 -> 0.022675463 | F12: 0 | H12: =$F12/$F$3 -> 0 | I12: 0 | K12: =$I12/$I$3 -> 0 | L12: 0 | N12: =$L12/$L$3 -> 0 | O12: 0 | Q12: =$O12/$O$3 -> 0 | R12: 0 | T12: =$R12/$R$3 -> 0 | U12: 0 | W12: =$U12/$U$3 -> 0 | X12: 0 | Y12: 100 | Z12: =X12/$X$3 -> 0
A13: 1.01.08 | B13: Outros Ativos Cirulantes | C13: 142235 | D13: =(C13/X13)*Y13 -> 144.30872 | E13: =C13/$C$3 -> 0.031841373 | F13: 96585 | G13: =(F$3/X13)*$Y13 -> 4648.6339 | H13: =$F13/$F$3 -> 0.021079991 | I13: 118748 | J13: =(I$3/X13)*$Y13 -> 4261.0564 | K13: =$I13/$I$3 -> 0.028274511 | L13: 132036 | M13: =(L$3/X13)*$Y13 -> 3808.8695 | N13: =$L13/$L$3 -> 0.035170809 | O13: 102245 | P13: =(O$3/X13)*$Y13 -> 2865.8168 | Q13: =$O13/$O$3 -> 0.036197597 | R13: 133370 | S13: =(R$3/X13)*$Y13 -> 1973.766 | T13: =$R13/$R$3 -> 0.068556489 | U13: 125939 | V13: =(U13/X13)*Y13 -> 127.77513 | W13: =$U13/$U$3 -> 0.070375501 | X13: 98563 | Y13: 100 | Z13: =X13/$X$3 -> 0.05684603
A14: 1.01.08.03 | B14: Outros | C14: 142235 | D14: =(C14/X14)*Y14 -> 144.30872 | E14: =C14/$C$3 -> 0.031841373 | F14: 96585 | G14: =(F$3/X14)*$Y14 -> 4648.6339 | H14: =$F14/$F$3 -> 0.021079991 | I14: 118748 | J14: =(I$3/X14)*$Y14 -> 4261.0564 | K14: =$I14/$I$3 -> 0.028274511 | L14: 132036 | M14: =(L$3/X14)*$Y14 -> 3808.8695 | N14: =$L14/$L$3 -> 0.035170809 | O14: 102245 | P14: =(O$3/X14)*$Y14 -> 2865.8168 | Q14: =$O14/$O$3 -> 0.036197597 | R14: 133370 | S14: =(R$3/X14)*$Y14 -> 1973.766 | T14: =$R14/$R$3 -> 0.068556489 | U14: 125939 | V14: =(U14/X14)*Y14 -> 127.77513 | W14: =$U14/$U$3 -> 0.070375501 | X14: 98563 | Y14: 100 | Z14: =X14/$X$3 -> 0.05684603
A15: 1.01.08.03.01 | B15: Partes Relacionadas | C15: 21658 | D15: =(C15/X15)*Y15 -> 174.90107 | E15: =C15/$C$3 -> 0.0048484583 | F15: 12382 | G15: =(F$3/X15)*$Y15 -> 37000.993 | H15: =$F15/$F$3 -> 0.0027024119 | I15: 13997 | J15: =(I$3/X15)*$Y15 -> 33916.054 | K15: =$I15/$I$3 -> 0.0033327579 | L15: 14502 | M15: =(L$3/X15)*$Y15 -> 30316.854 | N15: =$L15/$L$3 -> 0.0038629394 | O15: 20410 | P15: =(O$3/X15)*$Y15 -> 22810.587 | Q15: =$O15/$O$3 -> 0.0072257123 | R15: 20378 | S15: =(R$3/X15)*$Y15 -> 15710.272 | T15: =$R15/$R$3 -> 0.01047495 | U15: 21103 | V15: =(U15/X15)*Y15 -> 170.41912 | W15: =$U15/$U$3 -> 0.011792488 | X15: 12383 | Y15: 100 | Z15: =X15/$X$3 -> 0.0071418726
A16: 1.01.08.03.02 | B16: Outros Créditos | C16: 20037 | D16: =(C16/X16)*Y16 -> 84.359212 | E16: =C16/$C$3 -> 0.0044855738 | F16: 30680 | G16: =(F$3/X16)*$Y16 -> 19290.304 | H16: =$F16/$F$3 -> 0.0066960101 | I16: 43088 | J16: =(I$3/X16)*$Y16 -> 17681.985 | K16: =$I16/$I$3 -> 0.010259475 | L16: 56823 | M16: =(L$3/X16)*$Y16 -> 15805.557 | N16: =$L16/$L$3 -> 0.015136106 | O16: 28608 | P16: =(O$3/X16)*$Y16 -> 11892.199 | Q16: =$O16/$O$3 -> 0.010128034 | R16: 52457 | S16: =(R$3/X16)*$Y16 -> 8190.4808 | T16: =$R16/$R$3 -> 0.026964593 | U16: 36349 | V16: =(U16/X16)*Y16 -> 153.03553 | W16: =$U16/$U$3 -> 0.020312049 | X16: 23752 | Y16: 100 | Z16: =X16/$X$3 -> 0.013698922
A17: 1.02 | B17: Ativos Não Circulante | C17: 1499240 | D17: =(C17/X17)*Y17 -> 464.8417 | E17: =C17/$C$3 -> 0.33562668 | F17: 1006660 | G17: =(F$3/X17)*$Y17 -> 1420.6045 | H17: =$F17/$F$3 -> 0.21970683 | I17: 769763 | J17: =(I$3/X17)*$Y17 -> 1302.1623 | K17: =$I17/$I$3 -> 0.18328454 | L17: 634096 | M17: =(L$3/X17)*$Y17 -> 1163.9757 | N17: =$L17/$L$3 -> 0.16890597 | O17: 613398 | P17: =(O$3/X17)*$Y17 -> 875.78249 | Q17: =$O17/$O$3 -> 0.21716009 | R17: 473640 | S17: =(R$3/X17)*$Y17 -> 603.17524 | T17: =$R17/$R$3 -> 0.24346626 | U17: 370789 | V17: =(U17/X17)*Y17 -> 114.96371 | W17: =$U17/$U$3 -> 0.20719921 | X17: 322527 | Y17: 100 | Z17: =X17/$X$3 -> 0.18601686
A18: 1.02.01 | B18: Ativo Realizável a Longo Prazo | C18: 765802 | D18: =(C18/X18)*Y18 -> 511.69109 | E18: =C18/$C$3 -> 0.17143591 | F18: 502346 | G18: =(F$3/X18)*$Y18 -> 3061.4743 | H18: =$F18/$F$3 -> 0.10963865 | I18: 383872 | J18: =(I$3/X18)*$Y18 -> 2806.2254 | K18: =$I18/$I$3 -> 0.091401904 | L18: 339982 | M18: =(L$3/X18)*$Y18 -> 2508.4264 | N18: =$L18/$L$3 -> 0.090561983 | O18: 337585 | P18: =(O$3/X18)*$Y18 -> 1887.3554 | Q18: =$O18/$O$3 -> 0.11951456 | R18: 206351 | S18: =(R$3/X18)*$Y18 -> 1299.873 | T18: =$R18/$R$3 -> 0.10607108 | U18: 192540 | V18: =(U18/X18)*Y18 -> 128.65075 | W18: =$U18/$U$3 -> 0.10759256 | X18: 149661 | Y18: 100 | Z18: =X18/$X$3 -> 0.086316707
A19: 1.02.01.01 | B19: Aplicações Financeiras Avaliadas a Valor Justo através do Resultado | C19: 0 | E19: =C19/$C$3 -> 0 | F19: 0 | H19: =$F19/$F$3 -> 0 | I19: 0 | K19: =$I19/$I$3 -> 0 | L19: 0 | N19: =$L19/$L$3 -> 0 | O19: 0 | Q19: =$O19/$O$3 -> 0 | R19: 0 | T19: =$R19/$R$3 -> 0 | U19: 0 | W19: =$U19/$U$3 -> 0 | X19: 0 | Y19: 100 | Z19: =X19/$X$3 -> 0
A20: 1.02.01.04 | B20: Contas a Receber | C20: 185092 | D20: =(C20/X20)*Y20 -> 70645.802 | E20: =C20/$C$3 -> 0.041435536 | F20: 31972 | G20: =(F$3/X20)*$Y20 -> 1748791.2 | H20: =$F20/$F$3 -> 0.0069779933 | I20: 13573 | J20: =(I$3/X20)*$Y20 -> 1602986.6 | K20: =$I20/$I$3 -> 0.0032318013 | L20: 0 | M20: =(L$3/X20)*$Y20 -> 1432876.3 | N20: =$L20/$L$3 -> 0 | O20: 0 | P20: =(O$3/X20)*$Y20 -> 1078105 | Q20: =$O20/$O$3 -> 0 | R20: 70 | S20: =(R$3/X20)*$Y20 -> 742520.23 | T20: =$R20/$R$3 -> 3.5982262e-05 | U20: 28 | V20: =(U20/X20)*Y20 -> 10.687023 | W20: =$U20/$U$3 -> 1.5646575e-05 | X20: 262 | Y20: 100 | Z20: =X20/$X$3 -> 0.00015110802
A21: 1.02.01.07 | B21: Tributos Diferidos | C21: 1190 | D21: =(C21/X21)*Y21 -> 1.7832791 | E21: =C21/$C$3 -> 0.00026639881 | F21: 2743 | G21: =(F$3/X21)*$Y21 -> 6866.1237 | H21: =$F21/$F$3 -> 0.0005986687 | I21: 1712 | J21: =(I$3/X21)*$Y21 -> 6293.6641 | K21: =$I21/$I$3 -> 0.00040763603 | L21: 624 | M21: =(L$3/X21)*$Y21 -> 5625.7751 | N21: =$L21/$L$3 -> 0.00016621667 | O21: 599 | P21: =(O$3/X21)*$Y21 -> 4232.8678 | Q21: =$O21/$O$3 -> 0.0002120628 | R21: 60296 | S21: =(R$3/X21)*$Y21 -> 2915.2912 | T21: =$R21/$R$3 -> 0.030994092 | U21: 64744 | V21: =(U21/X21)*Y21 -> 97.022373 | W21: =$U21/$U$3 -> 0.036179352 | X21: 66731 | Y21: 100 | Z21: =X21/$X$3 -> 0.038486982
A22: 1.02.01.10 | B22: Outros Ativos Não Circulantes | C22: 579520 | D22: =(C22/X22)*Y22 -> 701.02095 | E22: =C22/$C$3 -> 0.12973398 | F22: 467631 | G22: =(F$3/X22)*$Y22 -> 5542.4505 | H22: =$F22/$F$3 -> 0.10206199 | I22: 368587 | J22: =(I$3/X22)*$Y22 -> 5080.3515 | K22: =$I22/$I$3 -> 0.087762466 | L22: 339358 | M22: =(L$3/X22)*$Y22 -> 4541.2203 | N22: =$L22/$L$3 -> 0.090395766 | O22: 336986 | P22: =(O$3/X22)*$Y22 -> 3416.8421 | Q22: =$O22/$O$3 -> 0.11930249 | R22: 145985 | S22: =(R$3/X22)*$Y22 -> 2353.2721 | T22: =$R22/$R$3 -> 0.075041007 | U22: 127768 | V22: =(U22/X22)*Y22 -> 154.55557 | W22: =$U22/$U$3 -> 0.071397558 | X22: 82668 | Y22: 100 | Z22: =X22/$X$3 -> 0.047678617
A23: 1.02.01.10.03 | B23: Tributos a Recuperar | C23: 501080 | D23: =(C23/X23)*Y23 -> 662.927 | E23: =C23/$C$3 -> 0.11217404 | F23: 457924 | G23: =(F$3/X23)*$Y23 -> 6061.7482 | H23: =$F23/$F$3 -> 0.099943407 | I23: 298614 | J23: =(I$3/X23)*$Y23 -> 5556.353 | K23: =$I23/$I$3 -> 0.071101534 | L23: 275722 | M23: =(L$3/X23)*$Y23 -> 4966.7081 | N23: =$L23/$L$3 -> 0.073444862 | O23: 275415 | P23: =(O$3/X23)*$Y23 -> 3736.9817 | Q23: =$O23/$O$3 -> 0.097504633 | R23: 86096 | S23: =(R$3/X23)*$Y23 -> 2573.761 | T23: =$R23/$R$3 -> 0.044256126 | U23: 75507 | V23: =(U23/X23)*Y23 -> 99.895483 | W23: =$U23/$U$3 -> 0.042193784 | X23: 75586 | Y23: 100 | Z23: =X23/$X$3 -> 0.043594087
A24: 1.02.01.10.04 | B24: Outros Ativos | C24: 2641 | D24: =(C24/X24)*Y24 -> 37.291726 | E24: =C24/$C$3 -> 0.00059122626 | F24: 9707 | G24: =(F$3/X24)*$Y24 -> 64696.879 | H24: =$F24/$F$3 -> 0.0021185844 | I24: 69973 | J24: =(I$3/X24)*$Y24 -> 59302.81 | K24: =$I24/$I$3 -> 0.016660932 | L24: 63636 | M24: =(L$3/X24)*$Y24 -> 53009.545 | N24: =$L24/$L$3 -> 0.016950904 | O24: 61571 | P24: =(O$3/X24)*$Y24 -> 39884.708 | Q24: =$O24/$O$3 -> 0.021797861 | R24: 59889 | S24: =(R$3/X24)*$Y24 -> 27469.684 | T24: =$R24/$R$3 -> 0.030784881 | U24: 52261 | V24: =(U24/X24)*Y24 -> 737.94126 | W24: =$U24/$U$3 -> 0.029203774 | X24: 7082 | Y24: 100 | Z24: =X24/$X$3 -> 0.0040845305
A25: 1.02.01.10.05 | B25: Depósitos Judiciais | C25: 35760 | E25: =C25/$C$3 -> 0.008005396 | F25: 0 | H25: =$F25/$F$3 -> 0 | I25: 0 | K25: =$I25/$I$3 -> 0 | L25: 0 | N25: =$L25/$L$3 -> 0 | O25: 0 | Q25: =$O25/$O$3 -> 0 | R25: 0 | T25: =$R25/$R$3 -> 0 | U25: 0 | W25: =$U25/$U$3 -> 0 | X25: 0 | Y25: 100 | Z25: =X25/$X$3 -> 0
B26: ATIVO FIXO | C26: =SUM(C27,C30,C33) -> 733438 | D26: =(C26/X26)*Y26 -> 424.28124 | E26: =C26/$C$3 -> 0.16419076 | F26: =SUM(F27,F30,F33) -> 504314 | G26: =(F$3/X26)*$Y26 -> 2650.5114 | H26: =$F26/$F$3 -> 0.11006818 | I26: =SUM(I27,I30,I33) -> 385891 | J26: =(I$3/X26)*$Y26 -> 2429.5263 | K26: =$I26/$I$3 -> 0.091882638 | L26: =SUM(L27,L30,L33) -> 294114 | M26: =(L$3/X26)*$Y26 -> 2171.7029 | N26: =$L26/$L$3 -> 0.078343992 | O26: =SUM(O27,O30,O33) -> 275813 | P26: =(O$3/X26)*$Y26 -> 1634.0026 | Q26: =$O26/$O$3 -> 0.097645537 | R26: =SUM(R27,R30,R33) -> 267289 | S26: =(R$3/X26)*$Y26 -> 1125.3821 | T26: =$R26/$R$3 -> 0.13739518 | U26: =SUM(U27,U30,U33) -> 178249 | V26: =(U26/X26)*Y26 -> 103.11397 | W26: =$U26/$U$3 -> 0.099606656 | X26: =SUM(X27,X30,X33) -> 172866 | Y26: 100 | Z26: =X26/$X$3 -> 0.099700149
A27: 1.02.02 | B27: Investimentos | C27: 256770 | D27: =(C27/X27)*Y27 -> 479.01276 | E27: =C27/$C$3 -> 0.057481699 | F27: 226969 | G27: =(F$3/X27)*$Y27 -> 8547.558 | H27: =$F27/$F$3 -> 0.049536725 | I27: 164127 | J27: =(I$3/X27)*$Y27 -> 7834.9097 | K27: =$I27/$I$3 -> 0.039079485 | L27: 114226 | M27: =(L$3/X27)*$Y27 -> 7003.4624 | N27: =$L27/$L$3 -> 0.030426708 | O27: 91692 | P27: =(O$3/X27)*$Y27 -> 5269.4482 | Q27: =$O27/$O$3 -> 0.032461539 | R27: 73433 | S27: =(R$3/X27)*$Y27 -> 3629.2124 | T27: =$R27/$R$3 -> 0.037746935 | U27: 48087 | V27: =(U27/X27)*Y27 -> 89.707858 | W27: =$U27/$U$3 -> 0.026871316 | X27: 53604 | Y27: 100 | Z27: =X27/$X$3 -> 0.030916009
A28: 1.02.02.01 | B28: Participações Societárias | C28: 256770 | D28: =(C28/X28)*Y28 -> 479.01276 | E28: =C28/$C$3 -> 0.057481699 | F28: 226969 | G28: =(F$3/X28)*$Y28 -> 8547.558 | H28: =$F28/$F$3 -> 0.049536725 | I28: 164127 | J28: =(I$3/X28)*$Y28 -> 7834.9097 | K28: =$I28/$I$3 -> 0.039079485 | L28: 114226 | M28: =(L$3/X28)*$Y28 -> 7003.4624 | N28: =$L28/$L$3 -> 0.030426708 | O28: 91692 | P28: =(O$3/X28)*$Y28 -> 5269.4482 | Q28: =$O28/$O$3 -> 0.032461539 | R28: 73433 | S28: =(R$3/X28)*$Y28 -> 3629.2124 | T28: =$R28/$R$3 -> 0.037746935 | U28: 48087 | V28: =(U28/X28)*Y28 -> 89.707858 | W28: =$U28/$U$3 -> 0.026871316 | X28: 53604 | Y28: 100 | Z28: =X28/$X$3 -> 0.030916009
A29: 1.02.02.01.01 | B29: Participações em Coligadas | C29: 136724 | E29: =C29/$C$3 -> 0.030607656 | F29: 226969 | H29: =$F29/$F$3 -> 0.049536725 | I29: 131714 | K29: =$I29/$I$3 -> 0.031361783 | L29: 76284 | N29: =$L29/$L$3 -> 0.020319988 | O29: 53154 | Q29: =$O29/$O$3 -> 0.018818007 | R29: 27317 | T29: =$R29/$R$3 -> 0.014041821 | U29: 8303 | W29: =$U29/$U$3 -> 0.0046397683 | X29: 0 | Y29: 100 | Z29: =X29/$X$3 -> 0
A30: 1.02.03 | B30: Imobilizado | C30: 155481 | D30: =(C30/X30)*Y30 -> 272.33413 | E30: =C30/$C$3 -> 0.034806683 | F30: 146818 | G30: =(F$3/X30)*$Y30 -> 8025.3503 | H30: =$F30/$F$3 -> 0.032043507 | I30: 110987 | J30: =(I$3/X30)*$Y30 -> 7356.2408 | K30: =$I30/$I$3 -> 0.026426577 | L30: 92894 | M30: =(L$3/X30)*$Y30 -> 6575.5903 | N30: =$L30/$L$3 -> 0.024744442 | O30: 86298 | P30: =(O$3/X30)*$Y30 -> 4947.5145 | Q30: =$O30/$O$3 -> 0.030551912 | R30: 88718 | S30: =(R$3/X30)*$Y30 -> 3407.4879 | T30: =$R30/$R$3 -> 0.045603919 | U30: 50746 | V30: =(U30/X30)*Y30 -> 88.884607 | W30: =$U30/$U$3 -> 0.028357182 | X30: 57092 | Y30: 100 | Z30: =X30/$X$3 -> 0.032927706
A31: 1.02.03.01 | B31: Imobilizado em Operação | C31: 125036 | E31: =C31/$C$3 -> 0.027991127 | F31: 116974 | H31: =$F31/$F$3 -> 0.025529957 | I31: 84915 | K31: =$I31/$I$3 -> 0.0202187 | L31: 60279 | N31: =$L31/$L$3 -> 0.016056691 | O31: 47700 | Q31: =$O31/$O$3 -> 0.016887138 | R31: 0 | T31: =$R31/$R$3 -> 0 | U31: 0 | W31: =$U31/$U$3 -> 0 | X31: 0 | Y31: 100 | Z31: =X31/$X$3 -> 0
A32: 1.02.03.02 | B32: Direito de Uso em Arrendamento | C32: 30445 | E32: =C32/$C$3 -> 0.006815556 | F32: 29844 | H32: =$F32/$F$3 -> 0.0065135504 | I32: 26072 | K32: =$I32/$I$3 -> 0.0062078777 | L32: 32615 | N32: =$L32/$L$3 -> 0.0086877513 | O32: 38598 | Q32: =$O32/$O$3 -> 0.013664774 | R32: 41694 | T32: =$R32/$R$3 -> 0.021432063 | U32: 0 | W32: =$U32/$U$3 -> 0 | X32: 0 | Y32: 100 | Z32: =X32/$X$3 -> 0
A33: 1.02.04 | B33: Intangível | C33: 321187 | D33: =(C33/X33)*Y33 -> 516.62699 | E33: =C33/$C$3 -> 0.071902381 | F33: 130527 | G33: =(F$3/X33)*$Y33 -> 7369.8456 | H33: =$F33/$F$3 -> 0.028487944 | I33: 110777 | J33: =(I$3/X33)*$Y33 -> 6755.3885 | K33: =$I33/$I$3 -> 0.026376575 | L33: 86994 | M33: =(L$3/X33)*$Y33 -> 6038.5009 | N33: =$L33/$L$3 -> 0.023172842 | O33: 97823 | P33: =(O$3/X33)*$Y33 -> 4543.4052 | Q33: =$O33/$O$3 -> 0.034632085 | R33: 105138 | S33: =(R$3/X33)*$Y33 -> 3129.1668 | T33: =$R33/$R$3 -> 0.054044329 | U33: 79416 | V33: =(U33/X33)*Y33 -> 127.74007 | W33: =$U33/$U$3 -> 0.044378158 | X33: 62170 | Y33: 100 | Z33: =X33/$X$3 -> 0.035856434
A34: 2 | B34: Passivo Total | C34: 4466987 | D34: =(C34/X34)*Y34 -> 257.63266 | E34: =C34/$C$3 -> 1 | F34: 4581833 | G34: =(F$3/X34)*$Y34 -> 264.25638 | H34: =$F34/$F$3 -> 1 | I34: 4199825 | J34: =(I$3/X34)*$Y34 -> 242.22414 | K34: =$I34/$I$3 -> 1 | L34: 3754136 | M34: =(L$3/X34)*$Y34 -> 216.51911 | N34: =$L$34/$L$34 -> 1 | O34: 2824635 | P34: =(O$3/X34)*$Y34 -> 162.91031 | Q34: =$O$34/$O$34 -> 1 | R34: 1945403 | S34: =(R$3/X34)*$Y34 -> 112.20076 | T34: =$R$34/$R$34 -> 1 | U34: 1789529 | V34: =(U34/X34)*Y34 -> 103.21076 | W34: =$U34/$U$34 -> 1 | X34: 1733859 | Y34: 100 | Z34: =X34/$X$3 -> 1
A35: 2.01 | B35: Passivo Circulante | C35: 1503102 | D35: =(C35/X35)*Y35 -> 137.8004 | E35: =C35/$C$3 -> 0.33649124 | F35: 1934265 | G35: =(F$3/X35)*$Y35 -> 420.05029 | H35: =$F35/$F$3 -> 0.42215965 | I35: 1773213 | J35: =(I$3/X35)*$Y35 -> 385.02881 | K35: =$I$3/$I$3 -> 1 | L35: 1937651 | M35: =(L$3/X35)*$Y35 -> 344.16923 | N35: =$L35/$L$34 -> 0.51613767 | O35: 1370932 | P35: =(O$3/X35)*$Y35 -> 258.95504 | Q35: =$O35/$O$34 -> 0.48534837 | R35: 1178943 | S35: =(R$3/X35)*$Y35 -> 178.34939 | T35: =$R35/$R$34 -> 0.60601479 | U35: 1111886 | V35: =(U35/X35)*Y35 -> 101.93476 | W35: =$U35/$U$34 -> 0.62132885 | X35: 1090782 | Y35: 100 | Z35: =X35/$X$3 -> 0.62910652
A36: 2.01.01 | B36: Obrigações Sociais e Trabalhistas | C36: 105953 | D36: =(C36/X36)*Y36 -> 526.55303 | E36: =C36/$C$3 -> 0.02371912 | F36: 80891 | H36: =$F36/$F$3 -> 0.017654725 | I36: 42753 | K36: =$I36/$I$35 -> 0.024110471 | L36: 38387 | N36: =$L36/$L$34 -> 0.010225256 | O36: 33263 | Q36: =$O36/$O$34 -> 0.011776035 | R36: 20281 | T36: =$R36/$R$34 -> 0.010425089 | U36: 18205 | W36: =$U36/$U$34 -> 0.010173068 | X36: 20122 | Y36: 100 | Z36: =X36/$X$3 -> 0.011605327
A37: 2.01.02 | B37: Fornecedores | C37: 658247 | D37: =(C37/X37)*Y37 -> 135.40249 | E37: =C37/$C$3 -> 0.14735816 | F37: 832121 | G37: =(F$3/X37)*$Y37 -> 942.49055 | H37: =$F37/$F$3 -> 0.18161312 | I37: 594245 | J37: =(I$3/X37)*$Y37 -> 863.91088 | K37: =$I37/$I$35 -> 0.3351233 | L37: 1186214 | M37: =(L$3/X37)*$Y37 -> 772.23192 | N37: =$L37/$L$34 -> 0.31597523 | O37: 562210 | P37: =(O$3/X37)*$Y37 -> 581.03205 | Q37: =$O37/$O$34 -> 0.19903811 | R37: 383964 | S37: =(R$3/X37)*$Y37 -> 400.17258 | T37: =$R37/$R$34 -> 0.1973699 | U37: 449260 | V37: =(U37/X37)*Y37 -> 92.413518 | W37: =$U37/$U$34 -> 0.2510493 | X37: 486141 | Y37: 100 | Z37: =X37/$X$3 -> 0.28038093
A38: 2.01.02.01 | B38: Fornecedores Nacionais | C38: 105953 | E38: =C38/$C$3 -> 0.02371912 | F38: 191211 | H38: =$F38/$F$3 -> 0.041732425 | I38: 290682 | K38: =$I38/$I$35 -> 0.16392954 | L38: 280741 | O38: 207963 | R38: 196025 | U38: 280194 | W38: =$U38/$U$34 -> 0.15657416 | X38: 0 | Y38: 100 | Z38: =X38/$X$3 -> 0
A39: 2.01.02.01.01 | B39: Fornecedores | C39: 167077 | E39: =C39/$C$3 -> 0.037402616 | F39: 0 | H39: =$F39/$F$3 -> 0 | I39: 0 | K39: =$I39/$I$35 -> 0 | L39: 0 | O39: 0 | R39: 0 | U39: 0 | W39: =$U39/$U$34 -> 0 | X39: 0 | Y39: 100 | Z39: =X39/$X$3 -> 0
A40: 2.01.02.01.02 | B40: Fornecedores - Convênio | C40: 491170 | E40: =C40/$C$3 -> 0.10995555 | F40: 0 | H40: =$F40/$F$3 -> 0 | I40: 0 | K40: =$I40/$I$35 -> 0 | L40: 0 | O40: 0 | R40: 0 | U40: 0 | W40: =$U40/$U$34 -> 0 | X40: 0 | Y40: 100 | Z40: =X40/$X$3 -> 0
...

Sheet DRE - AH e AV
A1: Demonstração do Resultado do Exercício - Análise Horizontal (ANO BASE 2017)
A2: Código da Conta | B2: Descrição da Conta | C2: 2024 | D2: AH 24 | E2: AV24 | F2: 2023 | G2: AH23 | H2: AV22 | I2: 2022 | J2: AH22 | K2: AV22 | L2: 2021 | M2: AH21 | N2: AV21 | O2: 2020 | P2: AH20 | Q2: AV20 | R2: 2019 | S2: AH19 | T2: AV19 | U2: 2018 | V2: AH18 | W2: AV18 | X2: 2017 | Y2: AH17 | Z2: AV17
A3: 3.01 | B3: Receita de Venda de Bens e/ou Serviços | C3: 3688326 | D3: =(C3/X3)*Y3 -> 1.9274198 | E3: =C3/C3 -> 1 | F3: 3926631 | G3: =(F3/X3)*$Y3 -> 2.0519516 | H3: =$F$3/$F$3 -> 1 | I3: 4993235 | J3: =(I3/X3)*$Y3 -> 2.6093301 | K3: =I3/$I$3 -> 1 | L3: 3365487 | M3: =(L3/X3)*$Y3 -> 1.7587129 | N3: =L3/L$3 -> 1 | O3: 2192173 | P3: =(O3/X3)*$Y3 -> 1.1455706 | Q3: =O3/O$3 -> 1 | R3: 1915308 | S3: =(R3/X3)*$Y3 -> 1.0008884 | T3: =R3/$R$3 -> 1 | U3: 1890654 | V3: =(U3/X3)*Y3 -> 0.98800486 | W3: =U3/$U$3 -> 1 | X3: 1913608 | Y3: 1 | Z3: =X3/X3 -> 1
A4: 3.02 | B4: Custo dos Bens e/ou Serviços Vendidos | C4: -2764289 | D4: =(C4/X4)*Y4 -> 1.9463274 | E4: =F4/C3 -> -0.77653168 | F4: -2864102 | G4: =(F4/X4)*$Y4 -> 2.0166054 | H4: =I4/$F$3 -> -0.96685377 | I4: -3796478 | J4: =(I4/X4)*$Y4 -> 2.6730885 | K4: =I4/$I$3 -> -0.76032432 | L4: -2596881 | M4: =(L4/X4)*$Y4 -> 1.8284559 | N4: =L4/L$3 -> -0.77162117 | O4: -1743427 | P4: =(O4/X4)*$Y4 -> 1.2275416 | Q4: =O4/O$3 -> -0.79529627 | R4: -1435200 | S4: =(R4/X4)*$Y4 -> 1.0105199 | T4: =R4/$R$3 -> -0.74933118 | U4: -1436949 | V4: =(U4/X4)*Y4 -> 1.0117514 | W4: =U4/$U$3 -> -0.76002748 | X4: -1420259 | Y4: 1 | Z4: =X4/$X$3 -> -0.7421891
A5: 3.03 | B5: Resultado Bruto | C5: 924037 | D5: =(C5/X5)*Y5 -> 1.8729885 | E5: =F5/C4 -> -0.38437696 | F5: 1062529 | G5: =(F5/X5)*$Y5 -> 2.1537066 | H5: =I5/$F$3 -> 0.30477959 | I5: 1196757 | J5: =(I5/X5)*$Y5 -> 2.4257817 | K5: =I5/$I$3 -> 0.23967568 | L5: 768606 | M5: =(L5/X5)*$Y5 -> 1.5579357 | N5: =L5/L$3 -> 0.22837883 | O5: 448746 | P5: =(O5/X5)*$Y5 -> 0.90959138 | Q5: =O5/O$3 -> 0.20470373 | R5: 480108 | S5: =(R5/X5)*$Y5 -> 0.97316099 | T5: =R5/$R$3 -> 0.25066882 | U5: 453705 | V5: =(U5/X5)*Y5 -> 0.91964309 | W5: =U5/$U$3 -> 0.23997252 | X5: 493349 | Y5: 1 | Z5: =X5/$X$3 -> 0.2578109
B6: Margem Bruta | C6: =C5/C3 -> 0.25053019 | D6: =(C6/X6)*Y6 -> 0.97175948 | E6: =F6/C5 -> 2.9284063e-07 | F6: =F5/F3 -> 0.27059558 | G6: =(F6/X6)*$Y6 -> 1.0495894 | H6: =I6/$F$3 -> 6.1038504e-08 | I6: =I5/I3 -> 0.23967568 | J6: =(I6/X6)*$Y6 -> 0.9296569 | L6: =L5/L3 -> 0.22837883 | M6: =(L6/X6)*$Y6 -> 0.88583856 | O6: =O5/O3 -> 0.20470373 | P6: =(O6/X6)*$Y6 -> 0.79400729 | R6: =R5/R3 -> 0.25066882 | S6: =(R6/X6)*$Y6 -> 0.97229722 | T6: =R6/$R$3 -> 1.3087651e-07 | U6: =U5/U3 -> 0.23997252 | V6: =(U6/X6)*Y6 -> 0.93080827 | W6: =U6/$U$3 -> 1.2692567e-07 | X6: =X5/X3 -> 0.2578109 | Y6: 1 | Z6: =X6/$X$3 -> 1.3472503e-07
A7: 3.04 | B7: Despesas/Receitas Operacionais | C7: -614527 | D7: =(C7/X7)*Y7 -> 1.3527732 | E7: =F7/C6 -> -2211118.8 | F7: -553952 | G7: =(F7/X7)*$Y7 -> 1.219428 | H7: =I7/$F$3 -> -0.14558587 | I7: -571662 | J7: =(I7/X7)*$Y7 -> 1.2584135 | K7: =I7/$I$3 -> -0.1144873 | L7: -465457 | M7: =(L7/X7)*$Y7 -> 1.0246218 | N7: =L7/L$3 -> -0.13830302 | O7: -171070 | P7: =(O7/X7)*$Y7 -> 0.37658055 | Q7: =O7/O$3 -> -0.078036724 | R7: -381253 | S7: =(R7/X7)*$Y7 -> 0.8392615 | T7: =R7/$R$3 -> -0.19905571 | U7: -378691 | V7: =(U7/X7)*Y7 -> 0.83362171 | W7: =U7/$U$3 -> -0.2002963 | X7: -454272 | Y7: 1 | Z7: =X7/$X$3 -> -0.23739031
B8: %Receita Líquida | D8: =(C8/X8)*Y8 -> 0 | E8: =F8/C7 -> 2.2956785e-07 | F8: =F7/F3 -> -0.14107564 | G8: =(F8/X8)*$Y8 -> 0.59427718 | H8: =I8/$F$3 -> -2.9156623e-08 | I8: =I7/I3 -> -0.1144873 | J8: =(I8/X8)*$Y8 -> 0.48227453 | K8: =I8/$I$3 -> -2.2928483e-08 | L8: =L7/L3 -> -0.13830302 | M8: =(L8/X8)*$Y8 -> 0.58259755 | O8: =O7/O3 -> -0.078036724 | P8: =(O8/X8)*$Y8 -> 0.3287275 | R8: =R7/R3 -> -0.19905571 | S8: =(R8/X8)*$Y8 -> 0.83851658 | T8: =R8/$R$3 -> -1.0392883e-07 | U8: =U7/U3 -> -0.2002963 | V8: =(U8/X8)*Y8 -> 0.84374252 | W8: =U8/$U$3 -> -1.0594022e-07 | X8: =X7/X3 -> -0.23739031 | Y8: 1 | Z8: =X8/$X$3 -> -1.2405378e-07
A9: 3.04.01 | B9: Despesas com Vendas | C9: -436329 | D9: =(C9/X9)*Y9 -> 1.31369 | F9: -496236 | G9: =(F9/X9)*$Y9 -> 1.4940567 | H9: =I9/$F$3 -> -0.1375897 | I9: -540264 | J9: =(I9/X9)*$Y9 -> 1.6266153 | K9: =I9/$I$3 -> -0.10819919 | L9: -363763 | M9: =(L9/X9)*$Y9 -> 1.0952099 | N9: =L9/L$3 -> -0.10808629 | O9: -310653 | P9: =(O9/X9)*$Y9 -> 0.9353074 | Q9: =O9/O$3 -> -0.14171007 | R9: -273006 | S9: =(R9/X9)*$Y9 -> 0.82196062 | T9: =R9/$R$3 -> -0.14253895 | U9: -276226 | V9: =(U9/X9)*Y9 -> 0.83165533 | W9: =U9/$U$3 -> -0.14610077 | X9: -332140 | Y9: 1 | Z9: =X9/$X$3 -> -0.17356742
A10: 3.04.02 | B10: Despesas Gerais e Administrativas | C10: 220817 | D10: =(C10/X10)*Y10 -> -2.2322786 | E10: =F10/C9 -> 0.49543349 | F10: -216172 | G10: =(F10/X10)*$Y10 -> 2.1853215 | H10: =I10/$F$3 -> -0.050253003 | I10: -197325 | J10: =(I10/X10)*$Y10 -> 1.9947938 | K10: =I10/$I$3 -> -0.039518468 | L10: -163437 | M10: =(L10/X10)*$Y10 -> 1.6522139 | N10: =L10/L$3 -> -0.04856266 | O10: -82691 | P10: =(O10/X10)*$Y10 -> 0.83593813 | Q10: =O10/O$3 -> -0.037721019 | R10: -112095 | S10: =(R10/X10)*$Y10 -> 1.1331884 | T10: =R10/$R$3 -> -0.058525835 | U10: -105148 | V10: =(U10/X10)*Y10 -> 1.06296 | W10: =U10/$U$3 -> -0.055614618 | X10: -98920 | Y10: 1 | Z10: =X10/$X$3 -> -0.051692928
